Workbook

Sheet Report
A1: Sales Report - Nour Fashion (Jun - Aug 2026)
A2: Built from the cleaned sales file. Every number below is a formula that reads the 'Cleaned Data' sheet. Revenue = Qty x Price (gross, includes cancelled/returned orders).
A4: Key numbers
A5: Metric | B5: Value
A6: Total orders | B6: =COUNTA('Cleaned Data'!$A$2:$A$451) -> 450
A7: Total revenue (EGP) | B7: =SUM('Cleaned Data'!$M$2:$M$451) -> 364210
A8: Cancelled + returned orders | B8: =COUNTIF('Cleaned Data'!$K$2:$K$451,"Cancelled")+COUNTIF('Cleaned Data'!$K$2:$K$451,"Returned") -> 136
A9: Cancelled + returned share | B9: =B8/B6 -> 0.30222222
A11: Top 5 products by revenue
A12: Ranked by revenue (not units): units are nearly flat across products, so price is what separates them.
A13: Rank | B13: Product | C13: Revenue (EGP) | D13: Units sold | E13: Orders
A14: 1 | B14: Jacket | C14: =SUMIFS('Cleaned Data'!$M$2:$M$451,'Cleaned Data'!$F$2:$F$451,B14) -> 66000 | D14: =SUMIFS('Cleaned Data'!$H$2:$H$451,'Cleaned Data'!$F$2:$F$451,B14) -> 66 | E14: =COUNTIFS('Cleaned Data'!$F$2:$F$451,B14) -> 46
A15: 2 | B15: Abaya | C15: =SUMIFS('Cleaned Data'!$M$2:$M$451,'Cleaned Data'!$F$2:$F$451,B15) -> 63000 | D15: =SUMIFS('Cleaned Data'!$H$2:$H$451,'Cleaned Data'!$F$2:$F$451,B15) -> 73 | E15: =COUNTIFS('Cleaned Data'!$F$2:$F$451,B15) -> 47
A16: 3 | B16: Sneakers | C16: =SUMIFS('Cleaned Data'!$M$2:$M$451,'Cleaned Data'!$F$2:$F$451,B16) -> 56050 | D16: =SUMIFS('Cleaned Data'!$H$2:$H$451,'Cleaned Data'!$F$2:$F$451,B16) -> 59 | E16: =COUNTIFS('Cleaned Data'!$F$2:$F$451,B16) -> 43
A17: 4 | B17: Dress | C17: =SUMIFS('Cleaned Data'!$M$2:$M$451,'Cleaned Data'!$F$2:$F$451,B17) -> 52500 | D17: =SUMIFS('Cleaned Data'!$H$2:$H$451,'Cleaned Data'!$F$2:$F$451,B17) -> 76 | E17: =COUNTIFS('Cleaned Data'!$F$2:$F$451,B17) -> 52
A18: 5 | B18: Jeans | C18: =SUMIFS('Cleaned Data'!$M$2:$M$451,'Cleaned Data'!$F$2:$F$451,B18) -> 36300 | D18: =SUMIFS('Cleaned Data'!$H$2:$H$451,'Cleaned Data'!$F$2:$F$451,B18) -> 69 | E18: =COUNTIFS('Cleaned Data'!$F$2:$F$451,B18) -> 44
A20: Orders by city
A21: Orders with an unknown city are left out of this table (see Cleaning Notes).
A22: City | B22: Orders | C22: Revenue (EGP)
A23: Cairo | B23: =COUNTIFS('Cleaned Data'!$E$2:$E$451,A23) -> 118 | C23: =SUMIFS('Cleaned Data'!$M$2:$M$451,'Cleaned Data'!$E$2:$E$451,A23) -> 95090
A24: Alexandria | B24: =COUNTIFS('Cleaned Data'!$E$2:$E$451,A24) -> 88 | C24: =SUMIFS('Cleaned Data'!$M$2:$M$451,'Cleaned Data'!$E$2:$E$451,A24) -> 68950
A25: Giza | B25: =COUNTIFS('Cleaned Data'!$E$2:$E$451,A25) -> 88 | C25: =SUMIFS('Cleaned Data'!$M$2:$M$451,'Cleaned Data'!$E$2:$E$451,A25) -> 69280
A26: Sohag | B26: =COUNTIFS('Cleaned Data'!$E$2:$E$451,A26) -> 41 | C26: =SUMIFS('Cleaned Data'!$M$2:$M$451,'Cleaned Data'!$E$2:$E$451,A26) -> 34530
A27: Mansoura | B27: =COUNTIFS('Cleaned Data'!$E$2:$E$451,A27) -> 37 | C27: =SUMIFS('Cleaned Data'!$M$2:$M$451,'Cleaned Data'!$E$2:$E$451,A27) -> 25970
A28: Assiut | B28: =COUNTIFS('Cleaned Data'!$E$2:$E$451,A28) -> 34 | C28: =SUMIFS('Cleaned Data'!$M$2:$M$451,'Cleaned Data'!$E$2:$E$451,A28) -> 34760
A29: Tanta | B29: =COUNTIFS('Cleaned Data'!$E$2:$E$451,A29) -> 24 | C29: =SUMIFS('Cleaned Data'!$M$2:$M$451,'Cleaned Data'!$E$2:$E$451,A29) -> 18690
A30: Top city (by orders) | B30: =INDEX(A23:A29,MATCH(MAX(B23:B29),B23:B29,0)) -> Cairo | C30: =MAX(B23:B29) -> 118
A33: Monthly sales
A34: Month | B34: Orders | C34: Revenue (EGP) | D34: Units sold
A35: 2026-06 | B35: =COUNTIFS('Cleaned Data'!$L$2:$L$451,A35) -> 119 | C35: =SUMIFS('Cleaned Data'!$M$2:$M$451,'Cleaned Data'!$L$2:$L$451,A35) -> 95100 | D35: =SUMIFS('Cleaned Data'!$H$2:$H$451,'Cleaned Data'!$L$2:$L$451,A35) -> 180
A36: 2026-07 | B36: =COUNTIFS('Cleaned Data'!$L$2:$L$451,A36) -> 167 | C36: =SUMIFS('Cleaned Data'!$M$2:$M$451,'Cleaned Data'!$L$2:$L$451,A36) -> 133960 | D36: =SUMIFS('Cleaned Data'!$H$2:$H$451,'Cleaned Data'!$L$2:$L$451,A36) -> 250
A37: 2026-08 | B37: =COUNTIFS('Cleaned Data'!$L$2:$L$451,A37) -> 164 | C37: =SUMIFS('Cleaned Data'!$M$2:$M$451,'Cleaned Data'!$L$2:$L$451,A37) -> 135150 | D37: =SUMIFS('Cleaned Data'!$H$2:$H$451,'Cleaned Data'!$L$2:$L$451,A37) -> 246

Sheet Cleaned Data
A1: Order ID | B1: Order Date | C1: Customer Name | D1: Phone | E1: City | F1: Product | G1: Category | H1: Qty | I1: Price | J1: Payment Method | K1: Status | L1: Month | M1: Revenue
A2: 1032 | B2: 46199 | C2: Ali Mahmoud | D2: 01169801375 | E2: Cairo | F2: Scarf | G2: Accessories | H2: 2 | I2: 120 | J2: Vodafone Cash | K2: Cancelled | L2: 2026-06 | M2: =IF(AND(ISNUMBER(H2),ISNUMBER(I2)),H2*I2,"") -> 240
A3: 1222 | B3: 46238 | C3: آية خليل | D3: 01573841107 | E3: Sohag | F3: Hoodie | G3: Tops | H3: 1 | I3: 450 | J3: Credit Card | K3: Delivered | L3: 2026-08 | M3: =IF(AND(ISNUMBER(H3),ISNUMBER(I3)),H3*I3,"") -> 450
A4: 1301 | B4: 46204 | C4: منى صلاح | D4: 01299957026 | E4: Alexandria | F4: Hoodie | G4: Tops | H4: 1 | I4: 450 | J4: Credit Card | K4: Delivered | L4: 2026-07 | M4: =IF(AND(ISNUMBER(H4),ISNUMBER(I4)),H4*I4,"") -> 450
A5: 1270 | B5: 46259 | C5: أحمد فتحي | D5: 01214951097 | E5: Giza | F5: Sneakers | G5: Shoes | H5: 2 | I5: 950 | J5: Cash On Delivery | K5: Delivered | L5: 2026-08 | M5: =IF(AND(ISNUMBER(H5),ISNUMBER(I5)),H5*I5,"") -> 1900
A6: 1001 | B6: 46177 | C6: Sara Hassan | D6: 01150165258 | F6: Scarf | G6: Accessories | H6: 1 | I6: 120 | J6: Credit Card | K6: Delivered | L6: 2026-06 | M6: =IF(AND(ISNUMBER(H6),ISNUMBER(I6)),H6*I6,"") -> 120
A7: 1387 | B7: 46225 | C7: عمر السيد | D7: Not provided | E7: Alexandria | F7: Sneakers | G7: Shoes | H7: 1 | I7: 950 | J7: Vodafone Cash | K7: Cancelled | L7: 2026-07 | M7: =IF(AND(ISNUMBER(H7),ISNUMBER(I7)),H7*I7,"") -> 950
A8: 1446 | B8: 46192 | C8: هدى عادل | D8: 01027937196 | E8: Cairo | F8: Jeans | G8: Bottoms | H8: 2 | I8: 550 | J8: Instapay | K8: Delivered | L8: 2026-06 | M8: =IF(AND(ISNUMBER(H8),ISNUMBER(I8)),H8*I8,"") -> 1100
A9: 1383 | B9: 46243 | C9: ياسمين حسن | D9: 01020992514 | E9: Cairo | F9: Sneakers | G9: Shoes | H9: 1 | I9: 950 | J9: Credit Card | K9: Returned | L9: 2026-08 | M9: =IF(AND(ISNUMBER(H9),ISNUMBER(I9)),H9*I9,"") -> 950
A10: 1425 | B10: 46257 | C10: رنا عادل | D10: 01517656586 | E10: Mansoura | F10: Hoodie | G10: Tops | H10: 1 | I10: 450 | J10: Instapay | K10: Returned | L10: 2026-08 | M10: =IF(AND(ISNUMBER(H10),ISNUMBER(I10)),H10*I10,"") -> 450
A11: 1217 | B11: 46192 | C11: منى صلاح | D11: 01039520262 | E11: Alexandria | F11: Sneakers | G11: Shoes | H11: 1 | I11: 950 | J11: Cash On Delivery | K11: Delivered | L11: 2026-06 | M11: =IF(AND(ISNUMBER(H11),ISNUMBER(I11)),H11*I11,"") -> 950
A12: 1125 | B12: 46213 | C12: أحمد إبراهيم | D12: Not provided | E12: Cairo | F12: Hoodie | G12: Tops | H12: 3 | I12: 450 | J12: Instapay | K12: Shipped | L12: 2026-07 | M12: =IF(AND(ISNUMBER(H12),ISNUMBER(I12)),H12*I12,"") -> 1350
A13: 1336 | B13: 46220 | C13: أحمد فتحي | D13: 01082244010 | E13: Cairo | F13: Sneakers | G13: Shoes | H13: 1 | I13: 950 | J13: Vodafone Cash | K13: Cancelled | L13: 2026-07 | M13: =IF(AND(ISNUMBER(H13),ISNUMBER(I13)),H13*I13,"") -> 950
A14: 1419 | B14: 46233 | C14: نور حسن | D14: 01246940799 | E14: Giza | F14: Jeans | G14: Bottoms | H14: 1 | I14: 550 | J14: Credit Card | K14: Delivered | L14: 2026-07 | M14: =IF(AND(ISNUMBER(H14),ISNUMBER(I14)),H14*I14,"") -> 550
A15: 1319 | B15: 46178 | C15: حسن حسن | D15: 01190676524 | E15: Tanta | F15: Dress | G15: Dresses | H15: 1 | I15: 750 | J15: Vodafone Cash | K15: Cancelled | L15: 2026-06 | M15: =IF(AND(ISNUMBER(H15),ISNUMBER(I15)),H15*I15,"") -> 750
A16: 1399 | B16: 46238 | C16: فاطمة رمضان | D16: 01156105767 | E16: Giza | F16: Dress | G16: Dresses | H16: 1 | I16: 750 | J16: Instapay | K16: Delivered | L16: 2026-08 | M16: =IF(AND(ISNUMBER(H16),ISNUMBER(I16)),H16*I16,"") -> 750
A17: 1051 | B17: 46219 | C17: سارة السيد | D17: 01114835122 | E17: Sohag | F17: Skirt | G17: Bottoms | H17: 2 | I17: 300 | J17: Instapay | K17: Delivered | L17: 2026-07 | M17: =IF(AND(ISNUMBER(H17),ISNUMBER(I17)),H17*I17,"") -> 600
A18: 1206 | B18: 46263 | C18: Esraa Ibrahim | D18: 01153485815 | E18: Giza | F18: Sneakers | G18: Shoes | H18: 1 | I18: 950 | J18: Instapay | K18: Delivered | L18: 2026-08 | M18: =IF(AND(ISNUMBER(H18),ISNUMBER(I18)),H18*I18,"") -> 950
... A33: 1078 | B33: 46240 | C33: يوسف يوسف | D33: 01136197238 | E33: Cairo | F33: Abaya | G33: Dresses | H33: 2 | I33: 900 | J33: Vodafone Cash | K33: Delivered | L33: 2026-08 | M33: =IF(AND(ISNUMBER(H33),ISNUMBER(I33)),H33*I33,"") -> 1800
A34: 1201 | B34: 46240 | C34: Yasmine Mahmoud | D34: 01227848126 | F34: Dress | G34: Dresses | H34: 2 | J34: Instapay | K34: Delivered | L34: 2026-08 | M34: =IF(AND(ISNUMBER(H34),ISNUMBER(I34)),H34*I34,"")
A35: 1082 | B35: 46242 | C35: Ahmed Saad | D35: 01216526560 | E35: Giza | F35: Jacket | G35: Outerwear | H35: 1 | I35: 1100 | J35: Cash On Delivery | K35: Cancelled | L35: 2026-08 | M35: =IF(AND(ISNUMBER(H35),ISNUMBER(I35)),H35*I35,"") -> 1100
A36: 1264 | B36: 46264 | C36: رنا محمود | D36: 01094171867 | E36: Alexandria | F36: T-Shirt | G36: Tops | H36: 1 | I36: 180 | J36: Credit Card | K36: Cancelled | L36: 2026-08 | M36: =IF(AND(ISNUMBER(H36),ISNUMBER(I36)),H36*I36,"") -> 180
A37: 1203 | B37: 46189 | C37: هدى السيد | D37: 01139291706 | E37: Cairo | F37: Dress | G37: Dresses | H37: 2 | I37: 750 | J37: Vodafone Cash | K37: Delivered | L37: 2026-06 | M37: =IF(AND(ISNUMBER(H37),ISNUMBER(I37)),H37*I37,"") -> 1500
A38: 1375 | B38: 46222 | C38: Mariam Hassan | D38: 01035134779 | E38: Cairo | F38: Blouse | G38: Tops | H38: 3 | I38: 320 | J38: Vodafone Cash | K38: Delivered | L38: 2026-07 | M38: =IF(AND(ISNUMBER(H38),ISNUMBER(I38)),H38*I38,"") -> 960
A39: 1162 | B39: 46216 | C39: منى عادل | D39: 01573406036 | E39: Giza | F39: Jeans | G39: Bottoms | H39: 2 | I39: 550 | J39: Credit Card | K39: Cancelled | L39: 2026-07 | M39: =IF(AND(ISNUMBER(H39),ISNUMBER(I39)),H39*I39,"") -> 1100
A40: 1288 | B40: 46228 | C40: مريم عبدالله | D40: 01526593358 | E40: Alexandria | F40: Jacket | G40: Outerwear | H40: 2 | I40: 1100 | J40: Credit Card | K40: Delivered | L40: 2026-07 | M40: =IF(AND(ISNUMBER(H40),ISNUMBER(I40)),H40*I40,"") -> 2200
A41: 1044 | B41: 46242 | C41: Ali Mahmoud | D41: 01266589120 | E41: Assiut | F41: Hoodie | G41: Tops | H41: 1 | I41: 450 | J41: Vodafone Cash | K41: Cancelled | L41: 2026-08 | M41: =IF(AND(ISNUMBER(H41),ISNUMBER(I41)),H41*I41,"") -> 450
A42: 1025 | B42: 46222 | C42: Youssef Hassan | D42: 01106617861 | E42: Cairo | F42: Skirt | G42: Bottoms | H42: 1 | I42: 300 | J42: Credit Card | K42: Returned | L42: 2026-07 | M42: =IF(AND(ISNUMBER(H42),ISNUMBER(I42)),H42*I42,"") -> 300
A43: 1049 | B43: 46209 | C43: Sara Mahmoud | D43: 01235254716 | E43: Cairo | F43: Blouse | G43: Tops | H43: 1 | I43: 320 | J43: Vodafone Cash | K43: Delivered | L43: 2026-07 | M43: =IF(AND(ISNUMBER(H43),ISNUMBER(I43)),H43*I43,"") -> 320
A44: 1118 | B44: 46191 | C44: نور رمضان | D44: 01105613279 | E44: Sohag | F44: Hoodie | G44: Tops | H44: 1 | I44: 450 | J44: Vodafone Cash | K44: Delivered | L44: 2026-06 | M44: =IF(AND(ISNUMBER(H44),ISNUMBER(I44)),H44*I44,"") -> 450
A45: 1272 | B45: 46242 | C45: يوسف عادل | D45: 01093465063 | E45: Assiut | F45: Jeans | G45: Bottoms | H45: 1 | I45: 550 | J45: Credit Card | K45: Delivered | L45: 2026-08 | M45: =IF(AND(ISNUMBER(H45),ISNUMBER(I45)),H45*I45,"") -> 550
A46: 1237 | B46: 46185 | C46: فاطمة عبدالله | D46: Not provided | E46: Sohag | F46: Jacket | G46: Outerwear | H46: 1 | I46: 1100 | J46: Cash On Delivery | K46: Cancelled | L46: 2026-06 | M46: =IF(AND(ISNUMBER(H46),ISNUMBER(I46)),H46*I46,"") -> 1100
... A51: 1398 | B51: 46231 | C51: سارة إبراهيم | D51: 01096347511 | E51: Cairo | F51: Jeans | G51: Bottoms | H51: 1 | I51: 550 | J51: Instapay | K51: Delivered | L51: 2026-07 | M51: =IF(AND(ISNUMBER(H51),ISNUMBER(I51)),H51*I51,"") -> 550
A52: 1358 | B52: 46243 | C52: رنا يوسف | D52: 01512314334 | E52: Alexandria | F52: Scarf | G52: Accessories | J52: Credit Card | K52: Delivered | L52: 2026-08 | M52: =IF(AND(ISNUMBER(H52),ISNUMBER(I52)),H52*I52,"")
A53: 1059 | B53: 46258 | C53: Youssef Ibrahim | D53: 01135139635 | E53: Cairo | F53: Dress | G53: Dresses | H53: 1 | I53: 750 | J53: Credit Card | K53: Cancelled | L53: 2026-08 | M53: =IF(AND(ISNUMBER(H53),ISNUMBER(I53)),H53*I53,"") -> 750
A54: 1364 | B54: 46245 | C54: ندى إبراهيم | D54: 01037190873 | E54: Giza | F54: Jacket | G54: Outerwear | H54: 1 | I54: 1100 | J54: Credit Card | K54: Cancelled | L54: 2026-08 | M54: =IF(AND(ISNUMBER(H54),ISNUMBER(I54)),H54*I54,"") -> 1100
A55: 1073 | B55: 46212 | C55: Yasmine Hassan | D55: 01051916768 | E55: Tanta | F55: Hoodie | G55: Tops | H55: 1 | I55: 450 | J55: Cash On Delivery | K55: Delivered | L55: 2026-07 | M55: =IF(AND(ISNUMBER(H55),ISNUMBER(I55)),H55*I55,"") -> 450
A56: 1062 | B56: 46227 | C56: منى فتحي | D56: 01181268518 | F56: Dress | G56: Dresses | H56: 1 | J56: Cash On Delivery | K56: Delivered | L56: 2026-07 | M56: =IF(AND(ISNUMBER(H56),ISNUMBER(I56)),H56*I56,"")
A57: 1094 | B57: 46189 | C57: Dina Ibrahim | D57: 01596732324 | E57: Mansoura | F57: Jeans | G57: Bottoms | H57: 4 | I57: 550 | J57: Credit Card | K57: Returned | L57: 2026-06 | M57: =IF(AND(ISNUMBER(H57),ISNUMBER(I57)),H57*I57,"") -> 2200
A58: 1108 | B58: 46217 | C58: دينا فتحي | D58: 01197553447 | E58: Sohag | F58: Hoodie | G58: Tops | H58: 1 | I58: 450 | J58: Credit Card | K58: Delivered | L58: 2026-07 | M58: =IF(AND(ISNUMBER(H58),ISNUMBER(I58)),H58*I58,"") -> 450
...

Sheet Cleaning Notes
A1: Cleaning Notes
A2: What was wrong with the raw file, what was done, and every assumption made.
A4: Row counts (from the raw-file audit)
A5: Item | B5: Rows | C5: Note
A6: Rows in raw file | B6: 486 | C6: Value from the raw Excel file
A7: Exact duplicate rows found | B7: 36 | C7: Duplicates are removed AFTER formatting is standardized
A8: Rows after cleaning | B8: =COUNTA('Cleaned Data'!$A$2:$A$451) -> 450 | C8: Live count from the 'Cleaned Data' sheet
A10: Missing values left after cleaning
A11: Column | B11: Blank cells | C11: Decision
A12: City | B12: =COUNTBLANK('Cleaned Data'!$E$2:$E$451) -> 20 | C12: Left blank. Unmapped values and the '-' placeholder are not guessed. These orders are excluded from the city table only.
A13: Qty | B13: =COUNTBLANK('Cleaned Data'!$H$2:$H$451) -> 5 | C13: Left blank. A guessed quantity would silently change totals.
A14: Price | B14: =COUNTBLANK('Cleaned Data'!$I$2:$I$451) -> 22 | C14: Left blank. Orders without a price have no revenue and are skipped by the revenue formulas.
A15: Orders without revenue | B15: =COUNTIF('Cleaned Data'!$M$2:$M$451,"") -> 25 | C15: Revenue totals are therefore slightly understated, not wrong.
A17: Issues found and how each was handled
A18: Column | C18: What was done
A19: Order Date | C19: Mixed formats (ISO, D/M/Y, D-Mon-Y, dotted, real dates) all converted to one date type. Dotted dates can be read two ways; the reading that falls inside the file's date range was used. Ambiguous cases default to day-first.
A20: City | C20: Arabic/English spellings, casing and abbreviations mapped to one English name per city.
A21: Price | C21: Text such as 'EGP 950', '950 جنيه' and '1,100' converted to numbers.
A22: Phone | C22: Unified to the 11-digit local format; '+20' removed; lost leading zeros restored.
A23: Product / Payment / Status | C23: Casing and spelling unified (e.g. Tshirt -> T-Shirt, COD -> Cash On Delivery).
A24: Qty | C24: The word 'two' converted to 2; placeholders left blank.
A25: Customer Name / Phone blanks | C25: Filled with a readable placeholder ('Not Found' / 'Not provided') because they are never used in a calculation.
A27: Data note: this practice project uses a simulated dataset that mimics a real messy export, so the business figures are illustrative.
